<robot
  name="Assem1">
  <link
    name="base_link">
    <inertial>
      <origin
        xyz="0.01016 0.00127 -0.00254"
        rpy="0 0 0" />
      <mass
        value="0.00037922" />
      <inertia
        ixx="1"
        ixy="1"
        ixz="1"
        iyy="1"
        iyz="1"
        izz="1" />
    </inertial>
    <visual>
      <origin
        xyz="0 0 0"
        rpy="0 0 0" />
      <geometry>
        <mesh
          filename="package://Assem1/meshes/base_link.STL" />
      </geometry>
      <material
        name="">
        <color
          rgba="1 0 0 1" />
      </material>
    </visual>
    <collision>
      <origin
        xyz="0 0 0"
        rpy="0 0 0" />
      <geometry>
        <mesh
          filename="package://Assem1/meshes/base_link.STL" />
      </geometry>
    </collision>
  </link>
  <link
    name="linkMid">
    <inertial>
      <origin
        xyz="0.0127 0.00127 -8.6736E-19"
        rpy="0 0 0" />
      <mass
        value="0.00037922" />
      <inertia
        ixx="1"
        ixy="1"
        ixz="1"
        iyy="1"
        iyz="1"
        izz="1" />
    </inertial>
    <visual>
      <origin
        xyz="0 0 0"
        rpy="0 0 0" />
      <geometry>
        <mesh
          filename="package://Assem1/meshes/linkMid.STL" />
      </geometry>
      <material
        name="">
        <color
          rgba="0 1 0 1" />
      </material>
    </visual>
    <collision>
      <origin
        xyz="0 0 0"
        rpy="0 0 0" />
      <geometry>
        <mesh
          filename="package://Assem1/meshes/linkMid.STL" />
      </geometry>
    </collision>
  </link>
  <joint
    name="Joint1"
    type="revolute">
    <origin
      xyz="0.02286 0.00254 0.00254"
      rpy="1.5708 -4.9716E-20 -0.00081194" />
    <parent
      link="base_link" />
    <child
      link="linkMid" />
    <axis
      xyz="0 1 0" />
    <limit
      effort="0"
      velocity="0" />
  </joint>
  <link
    name="LinkEnd">
    <inertial>
      <origin
        xyz="-0.0127 0.00127 -8.6736E-19"
        rpy="0 0 0" />
      <mass
        value="0.00037922" />
      <inertia
        ixx="1"
        ixy="1"
        ixz="1"
        iyy="1"
        iyz="1"
        izz="1" />
    </inertial>
    <visual>
      <origin
        xyz="0 0 0"
        rpy="0 0 0" />
      <geometry>
        <mesh
          filename="package://Assem1/meshes/LinkEnd.STL" />
      </geometry>
      <material
        name="">
        <color
          rgba="0 0 1 1" />
      </material>
    </visual>
    <collision>
      <origin
        xyz="0 0 0"
        rpy="0 0 0" />
      <geometry>
        <mesh
          filename="package://Assem1/meshes/LinkEnd.STL" />
      </geometry>
    </collision>
  </link>
  <joint
    name="Joint2"
    type="revolute">
    <origin
      xyz="0.0254000000000002 0.00254 0"
      rpy="3.14159265358979 -0.00173475071437745 -3.14159265358979" />
    <parent
      link="linkMid" />
    <child
      link="LinkEnd" />
    <axis
      xyz="0 1 0" />
  </joint>
</robot>