<robot
  name="urdfAttempt3.urdf">
  <link
    name="basicArmModel">
    <inertial>
      <origin
        xyz="-0.0513027812094699 -4.51786481406517E-18 -0.0671295095824389"
        rpy="0 0 0" />
      <mass
        value="0.218540176386208" />
      <inertia
        ixx="6.12769930504918E-05"
        ixy="2.00458349935325E-20"
        ixz="8.54139203116646E-05"
        iyy="0.000218895135984386"
        iyz="-7.98472703931539E-21"
        izz="0.000157618142933894" />
    </inertial>
    <visual>
      <origin
        xyz="0 0 0"
        rpy="0 0 0" />
      <geometry>
        <mesh
          filename="package://urdfAttempt3.urdf/meshes/basicArmModel.STL" />
      </geometry>
      <material
        name="">
        <color
          rgba="0.792156862745098 0.819607843137255 0.933333333333333 1" />
      </material>
    </visual>
    <collision>
      <origin
        xyz="0 0 0"
        rpy="0 0 0" />
      <geometry>
        <mesh
          filename="package://urdfAttempt3.urdf/meshes/basicArmModel.STL" />
      </geometry>
    </collision>
  </link>
  <link
    name="Top_Link">
    <inertial>
      <origin
        xyz="-0.171638557485766 0.0865389449678522 4.00993662224418E-17"
        rpy="0 0 0" />
      <mass
        value="0.00343500504147382" />
      <inertia
        ixx="0"
        ixy="0"
        ixz="0"
        iyy="0"
        iyz="0"
        izz="0" />
    </inertial>
    <visual>
      <origin
        xyz="0 0 0"
        rpy="0 0 0" />
      <geometry>
        <mesh
          filename="package://urdfAttempt3.urdf/meshes/Top_Link.STL" />
      </geometry>
      <material
        name="">
        <color
          rgba="0.792156862745098 0.819607843137255 0.933333333333333 1" />
      </material>
    </visual>
    <collision>
      <origin
        xyz="0 0 0"
        rpy="0 0 0" />
      <geometry>
        <mesh
          filename="package://urdfAttempt3.urdf/meshes/Top_Link.STL" />
      </geometry>
    </collision>
  </link>
  <joint
    name="Top_Joint"
    type="fixed">
    <origin
      xyz="0.0015681 0 -0.18369"
      rpy="1.5708 0.73406 -5.5245E-17" />
    <parent
      link="basicArmModel" />
    <child
      link="Top_Link" />
    <axis
      xyz="0 0 0" />
  </joint>
  <link
    name="Middle_Link">
    <inertial>
      <origin
        xyz="-4.48350371141937E-06 0.0178000000000011 -2.99206319174846E-18"
        rpy="0 0 0" />
      <mass
        value="0.141480656645557" />
      <inertia
        ixx="0"
        ixy="0"
        ixz="0"
        iyy="0"
        iyz="0"
        izz="0" />
    </inertial>
    <visual>
      <origin
        xyz="0 0 0"
        rpy="0 0 0" />
      <geometry>
        <mesh
          filename="package://urdfAttempt3.urdf/meshes/Middle_Link.STL" />
      </geometry>
      <material
        name="">
        <color
          rgba="0.792156862745098 0.819607843137255 0.933333333333333 1" />
      </material>
    </visual>
    <collision>
      <origin
        xyz="0 0 0"
        rpy="0 0 0" />
      <geometry>
        <mesh
          filename="package://urdfAttempt3.urdf/meshes/Middle_Link.STL" />
      </geometry>
    </collision>
  </link>
  <joint
    name="Middle_Joint"
    type="revolute">
    <origin
      xyz="-0.085641 0 -0.049486"
      rpy="-1.5708 1.1092 -3.1416" />
    <parent
      link="basicArmModel" />
    <child
      link="Middle_Link" />
    <axis
      xyz="1 0 0" />
    <limit
      effort="0"
      velocity="0" />
  </joint>
  <link
    name="Bottom_Link">
    <inertial>
      <origin
        xyz="5.55111512312578E-17 0.0110000000000006 1.74728048199829E-17"
        rpy="0 0 0" />
      <mass
        value="0.00684520355262773" />
      <inertia
        ixx="0"
        ixy="0"
        ixz="0"
        iyy="0"
        iyz="0"
        izz="0" />
    </inertial>
    <visual>
      <origin
        xyz="0 0 0"
        rpy="0 0 0" />
      <geometry>
        <mesh
          filename="package://urdfAttempt3.urdf/meshes/Bottom_Link.STL" />
      </geometry>
      <material
        name="">
        <color
          rgba="0.792156862745098 0.819607843137255 0.933333333333333 1" />
      </material>
    </visual>
    <collision>
      <origin
        xyz="0 0 0"
        rpy="0 0 0" />
      <geometry>
        <mesh
          filename="package://urdfAttempt3.urdf/meshes/Bottom_Link.STL" />
      </geometry>
    </collision>
  </link>
  <joint
    name="Bottom_Joint"
    type="revolute">
    <origin
      xyz="-0.05498 0 -0.10266"
      rpy="1.5708 -0.10405 6.3939E-18" />
    <parent
      link="basicArmModel" />
    <child
      link="Bottom_Link" />
    <axis
      xyz="1 0 0" />
    <limit
      effort="0"
      velocity="0" />
  </joint>
  <link
    name="Base_Link">
    <inertial>
      <origin
        xyz="0.024825 0.017928 3.7667E-18"
        rpy="0 0 0" />
      <mass
        value="0.066779" />
      <inertia
        ixx="0"
        ixy="0"
        ixz="0"
        iyy="0"
        iyz="0"
        izz="0" />
    </inertial>
    <visual>
      <origin
        xyz="0 0 0"
        rpy="0 0 0" />
      <geometry>
        <mesh
          filename="package://urdfAttempt3.urdf/meshes/Base_Link.STL" />
      </geometry>
      <material
        name="">
        <color
          rgba="0.79216 0.81961 0.93333 1" />
      </material>
    </visual>
    <collision>
      <origin
        xyz="0 0 0"
        rpy="0 0 0" />
      <geometry>
        <mesh
          filename="package://urdfAttempt3.urdf/meshes/Base_Link.STL" />
      </geometry>
    </collision>
  </link>
  <joint
    name="Base_Joint"
    type="revolute">
    <origin
      xyz="-0.035749 0 -0.10642"
      rpy="1.5708 -0.0027547 1.6867E-19" />
    <parent
      link="basicArmModel" />
    <child
      link="Base_Link" />
    <axis
      xyz="1 0 0" />
    <limit
      effort="0"
      velocity="0" />
  </joint>
</robot>