<robot
  name="3Arm10.4.SLDASM">
  <link
    name="base_link">
    <inertial>
      <origin
        xyz="0.01016 0.00254 0.00127"
        rpy="0 0 0" />
      <mass
        value="0.00037922" />
      <inertia
        ixx="0"
        ixy="0"
        ixz="0"
        iyy="0"
        iyz="0"
        izz="0" />
    </inertial>
    <visual>
      <origin
        xyz="0 0 0"
        rpy="0 0 0" />
      <geometry>
        <mesh
          filename="package://3Arm10.4.SLDASM/meshes/base_link.STL" />
      </geometry>
      <material
        name="">
        <color
          rgba="0.75294 0.75294 0.75294 1" />
      </material>
    </visual>
    <collision>
      <origin
        xyz="0 0 0"
        rpy="0 0 0" />
      <geometry>
        <mesh
          filename="package://3Arm10.4.SLDASM/meshes/base_link.STL" />
      </geometry>
    </collision>
  </link>
  <link
    name="linkMid">
    <inertial>
      <origin
        xyz="0.0127 0.00127 -8.6736E-19"
        rpy="0 0 0" />
      <mass
        value="0.00037922" />
      <inertia
        ixx="0"
        ixy="0"
        ixz="0"
        iyy="0"
        iyz="0"
        izz="0" />
    </inertial>
    <visual>
      <origin
        xyz="0 0 0"
        rpy="0 0 0" />
      <geometry>
        <mesh
          filename="package://3Arm10.4.SLDASM/meshes/linkMid.STL" />
      </geometry>
      <material
        name="">
        <color
          rgba="0 1 0 1" />
      </material>
    </visual>
    <collision>
      <origin
        xyz="0 0 0"
        rpy="0 0 0" />
      <geometry>
        <mesh
          filename="package://3Arm10.4.SLDASM/meshes/linkMid.STL" />
      </geometry>
    </collision>
  </link>
  <joint
    name="Joint1"
    type="revolute">
    <origin
      xyz="0.02286 0.00254 0.00254"
      rpy="1.5707963267949 -4.97156174130486E-20 -0.000811944552147837" />
    <parent
      link="base_link" />
    <child
      link="linkMid" />
    <axis
      xyz="0 1 0" />
  </joint>
  <link
    name="LinkMid2">
    <inertial>
      <origin
        xyz="-0.0127 0.00127 -4.3368E-19"
        rpy="0 0 0" />
      <mass
        value="0.00037922" />
      <inertia
        ixx="0"
        ixy="0"
        ixz="0"
        iyy="0"
        iyz="0"
        izz="0" />
    </inertial>
    <visual>
      <origin
        xyz="0 0 0"
        rpy="0 0 0" />
      <geometry>
        <mesh
          filename="package://3Arm10.4.SLDASM/meshes/LinkMid2.STL" />
      </geometry>
      <material
        name="">
        <color
          rgba="1 0 0 1" />
      </material>
    </visual>
    <collision>
      <origin
        xyz="0 0 0"
        rpy="0 0 0" />
      <geometry>
        <mesh
          filename="package://3Arm10.4.SLDASM/meshes/LinkMid2.STL" />
      </geometry>
    </collision>
  </link>
  <joint
    name="Joint2"
    type="revolute">
    <origin
      xyz="0.0254 0.00254 0"
      rpy="3.1416 -0.0017348 -3.1416" />
    <parent
      link="linkMid" />
    <child
      link="LinkMid2" />
    <axis
      xyz="0 1 0" />
    <limit
      effort="0"
      velocity="0" />
  </joint>
  <link
    name="LinkEnd">
    <inertial>
      <origin
        xyz="-0.0127 -0.00127 -4.3368E-19"
        rpy="0 0 0" />
      <mass
        value="0.00037922" />
      <inertia
        ixx="0"
        ixy="0"
        ixz="0"
        iyy="0"
        iyz="0"
        izz="0" />
    </inertial>
    <visual>
      <origin
        xyz="0 0 0"
        rpy="0 0 0" />
      <geometry>
        <mesh
          filename="package://3Arm10.4.SLDASM/meshes/LinkEnd.STL" />
      </geometry>
      <material
        name="">
        <color
          rgba="0 0 1 1" />
      </material>
    </visual>
    <collision>
      <origin
        xyz="0 0 0"
        rpy="0 0 0" />
      <geometry>
        <mesh
          filename="package://3Arm10.4.SLDASM/meshes/LinkEnd.STL" />
      </geometry>
    </collision>
  </link>
  <joint
    name="Joint3"
    type="continuous">
    <origin
      xyz="0.0508 -0.00508 6.7502E-05"
      rpy="3.1416 0.00092281 3.1416" />
    <parent
      link="LinkMid2" />
    <child
      link="LinkEnd" />
    <axis
      xyz="0 1 0" />
  </joint>
</robot>