<robot
  name="Assem2Analysis.SLDASM">
  <link
    name="basicArmModel">
    <inertial>
      <origin
        xyz="-0.051263 -0.067091 -7.8118E-18"
        rpy="0 0 0" />
      <mass
        value="0.21854" />
      <inertia
        ixx="6.2344E-05"
        ixy="8.498E-05"
        ixz="-4.9069E-20"
        iyy="0.00015735"
        iyz="4.1386E-20"
        izz="0.00021969" />
    </inertial>
    <visual>
      <origin
        xyz="0 0 0"
        rpy="0 0 0" />
      <geometry>
        <mesh
          filename="package://Assem2Analysis.SLDASM/meshes/basicArmModel.STL" />
      </geometry>
      <material
        name="">
        <color
          rgba="0.79216 0.81961 0.93333 1" />
      </material>
    </visual>
    <collision>
      <origin
        xyz="0 0 0"
        rpy="0 0 0" />
      <geometry>
        <mesh
          filename="package://Poppy_Ergo/meshes/flat_base.STL" />
      </geometry>
    </collision>
  </link>


  <link
    name="Top_Link">
    <inertial>
      <origin
        xyz="-0.17164 0.086539 4.1248E-17"
        rpy="0 0 0" />
      <mass
        value="0.003435" />
      <inertia
        ixx="1.34906671319978E-06"
        ixy="-6.75990848930974E-15"
        ixz="-9.2900996309437E-10"
        iyy="2.56110628664785E-06"
        iyz="2.75193579105881E-11"
        izz="2.08267318891963E-06" />
    </inertial>
    <visual>
      <origin
        xyz="0 0 0"
        rpy="0 0 0" />
      <geometry>
        <mesh
          filename="package://Poppy_Ergo/meshes/U_shape.STL" />
      </geometry>
      <material
        name="">
        <color
          rgba="0.79216 0.81961 0.93333 1" />
      </material>
    </visual>
    <collision>
      <origin
        xyz="0 0 0"
        rpy="0 0 0" />
      <geometry>
        <mesh
          filename="package://Poppy_Ergo/meshes/U_shape.STL" />
      </geometry>
    </collision>
  </link>


  <joint
    name="Top_Joint"
    type="revolute">
    <origin
      xyz="0.0015681 0 -0.18369"
      rpy="1.5708 0.73406 -5.5245E-17" />
    <parent
      link="basicArmModel" />
    <child
      link="Top_Link" />
    <axis
      xyz="0 1 0" />
  </joint>


  <link
    name="Middle_Link">
    <inertial>
      <origin
        xyz="-4.4835E-06 0.0178 -3.1324E-18"
        rpy="0 0 0" />
      <mass
        value="0.14148" />
      <inertia
        ixx="2.88062730000748E-05"
        ixy="-4.09554328793376E-07"
        ixz="6.38110786400718E-13"
        iyy="1.69994170120842E-05"
        iyz="-3.08410026385581E-12"
        izz="3.50518702024955E-05" />
    </inertial>
    <visual>
      <origin
        xyz="0 0 0"
        rpy="0 0 0" />
      <geometry>
        <mesh
          filename="package://Poppy_Ergo/meshes/module_1.STL" />
      </geometry>
      <material
        name="">
        <color
          rgba="0.79216 0.81961 0.93333 1" />
      </material>
    </visual>
    <collision>
      <origin
        xyz="0 0 0"
        rpy="0 0 0" />
      <geometry>
        <mesh
          filename="package://Poppy_Ergo/meshes/module_1.STL" />
      </geometry>
    </collision>
  </link>



  <joint
    name="Middle_Joint"
    type="revolute">
    <origin
      xyz="-0.085641 0 -0.049486"
      rpy="-1.5708 1.1092 -3.1416" />
    <parent
      link="basicArmModel" />
    <child
      link="Middle_Link" />
    <axis
      xyz="0 1 0" />
  </joint>


  <link
    name="Bottom_Link">
    <inertial>
      <origin
        xyz="5.5511E-17 0.011 1.5811E-17"
        rpy="0 0 0" />
      <mass
        value="0.0068452" />
      <inertia
        ixx="2.09487833891956E-05"
        ixy="-3.96948279691612E-07"
        ixz="1.02565194835031E-12"
        iyy="1.52176900602456E-05"
        iyz="-7.79389983932002E-11"
        izz="2.6045998949051E-05" />
    </inertial>
    <visual>
      <origin
        xyz="0 0 0"
        rpy="0 0 0" />
      <geometry>
        <mesh
          filename="package://Poppy_Ergo/meshes/base_module_2.STL" />
      </geometry>
      <material
        name="">
        <color
          rgba="0.79216 0.81961 0.93333 1" />
      </material>
    </visual>
    <collision>
      <origin
        xyz="0 0 0"
        rpy="0 0 0" />
      <geometry>
        <mesh
          filename="package://Assem2Analysis.SLDASM/meshes/Bottom_Link.STL" />
      </geometry>
    </collision>
  </link>


  <joint
    name="Bottom_Joint"
    type="revolute">
    <origin
      xyz="-0.05498 0 -0.10266"
      rpy="1.5708 -0.10405 6.3939E-18" />
    <parent
      link="basicArmModel" />
    <child
      link="Bottom_Link" />
    <axis
      xyz="0 1 0" />
  </joint>


  <link
    name="Base_Link">
    <inertial>
      <origin
        xyz="0.024825 0.017928 3.742E-18"
        rpy="0 0 0" />
      <mass
        value="0.066779" />
      <inertia
        ixx="3.21637538420152E-05"
        ixy="-4.09394482193692E-11"
        ixz="-2.90206953011626E-09"
        iyy="2.9160553499979E-05"
        iyz="1.02861084202199E-06"
        izz="1.6137578673269E-05" />
    </inertial>
    <visual>
      <origin
        xyz="0 0 0"
        rpy="0 0 0" />
      <geometry>
        <mesh
          filename="package://Poppy_Ergo/meshes/tip_module_1.STL" />
      </geometry>
      <material
        name="">
        <color
          rgba="0.79216 0.81961 0.93333 1" />
      </material>
    </visual>
    <collision>
      <origin
        xyz="0 0 0"
        rpy="0 0 0" />
      <geometry>
        <mesh
          filename="package://Assem2Analysis.SLDASM/meshes/Base_Link.STL" />
      </geometry>
    </collision>
  </link>


  <joint
    name="Base_Joint"
    type="revolute">
    <origin
      xyz="-0.035749 0 -0.10642"
      rpy="1.5708 -0.0027547 1.6867E-19" />
    <parent
      link="basicArmModel" />
    <child
      link="Base_Link" />
    <axis
      xyz="0 1 0" />
  </joint>


</robot>